2023-06-22 17:25:09,173 ERROR Internal Server Error: /admin/News/author/ C:\Users\1\PycharmProjects\pythonProject3\venv\lib\site-packages\django\utils\log.py (<class 'django.db.utils.OperationalError'>, OperationalError('no such column: News_author.rating'), <traceback object at 0x00000000064D0C40>)
Traceback (most recent call last):
  File "C:\Users\1\PycharmProjects\pythonProject3\venv\lib\site-packages\django\db\backends\utils.py", line 89, in _execute
    return self.cursor.execute(sql, params)
  File "C:\Users\1\PycharmProjects\pythonProject3\venv\lib\site-packages\django\db\backends\sqlite3\base.py", line 328, in execute
    return super().execute(query, params)
sqlite3.OperationalError: no such column: News_author.rating

The above exception was the direct cause of the following exception:

Traceback (most recent call last):
  File "C:\Users\1\PycharmProjects\pythonProject3\venv\lib\site-packages\django\core\handlers\exception.py", line 55, in inner
    response = get_response(request)
  File "C:\Users\1\PycharmProjects\pythonProject3\venv\lib\site-packages\django\core\handlers\base.py", line 197, in _get_response
    response = wrapped_callback(request, *callback_args, **callback_kwargs)
  File "C:\Users\1\PycharmProjects\pythonProject3\venv\lib\site-packages\django\contrib\admin\options.py", line 688, in wrapper
    return self.admin_site.admin_view(view)(*args, **kwargs)
  File "C:\Users\1\PycharmProjects\pythonProject3\venv\lib\site-packages\django\utils\decorators.py", line 134, in _wrapper_view
    response = view_func(request, *args, **kwargs)
  File "C:\Users\1\PycharmProjects\pythonProject3\venv\lib\site-packages\django\views\decorators\cache.py", line 62, in _wrapper_view_func
    response = view_func(request, *args, **kwargs)
  File "C:\Users\1\PycharmProjects\pythonProject3\venv\lib\site-packages\django\contrib\admin\sites.py", line 242, in inner
    return view(request, *args, **kwargs)
  File "C:\Users\1\PycharmProjects\pythonProject3\venv\lib\site-packages\django\utils\decorators.py", line 46, in _wrapper
    return bound_method(*args, **kwargs)
  File "C:\Users\1\PycharmProjects\pythonProject3\venv\lib\site-packages\django\utils\decorators.py", line 134, in _wrapper_view
    response = view_func(request, *args, **kwargs)
  File "C:\Users\1\PycharmProjects\pythonProject3\venv\lib\site-packages\django\contrib\admin\options.py", line 2065, in changelist_view
    "selection_note": _("0 of %(cnt)s selected") % {"cnt": len(cl.result_list)},
  File "C:\Users\1\PycharmProjects\pythonProject3\venv\lib\site-packages\django\db\models\query.py", line 380, in __len__
    self._fetch_all()
  File "C:\Users\1\PycharmProjects\pythonProject3\venv\lib\site-packages\django\db\models\query.py", line 1881, in _fetch_all
    self._result_cache = list(self._iterable_class(self))
  File "C:\Users\1\PycharmProjects\pythonProject3\venv\lib\site-packages\django\db\models\query.py", line 91, in __iter__
    results = compiler.execute_sql(
  File "C:\Users\1\PycharmProjects\pythonProject3\venv\lib\site-packages\django\db\models\sql\compiler.py", line 1560, in execute_sql
    cursor.execute(sql, params)
  File "C:\Users\1\PycharmProjects\pythonProject3\venv\lib\site-packages\django\db\backends\utils.py", line 102, in execute
    return super().execute(sql, params)
  File "C:\Users\1\PycharmProjects\pythonProject3\venv\lib\site-packages\django\db\backends\utils.py", line 67, in execute
    return self._execute_with_wrappers(
  File "C:\Users\1\PycharmProjects\pythonProject3\venv\lib\site-packages\django\db\backends\utils.py", line 80, in _execute_with_wrappers
    return executor(sql, params, many, context)
  File "C:\Users\1\PycharmProjects\pythonProject3\venv\lib\site-packages\django\db\backends\utils.py", line 89, in _execute
    return self.cursor.execute(sql, params)
  File "C:\Users\1\PycharmProjects\pythonProject3\venv\lib\site-packages\django\db\utils.py", line 91, in __exit__
    raise dj_exc_value.with_traceback(traceback) from exc_value
  File "C:\Users\1\PycharmProjects\pythonProject3\venv\lib\site-packages\django\db\backends\utils.py", line 89, in _execute
    return self.cursor.execute(sql, params)
  File "C:\Users\1\PycharmProjects\pythonProject3\venv\lib\site-packages\django\db\backends\sqlite3\base.py", line 328, in execute
    return super().execute(query, params)
django.db.utils.OperationalError: no such column: News_author.rating
2023-06-22 17:25:09,180 ERROR "GET /admin/News/author/ HTTP/1.1" 500 166342 C:\Users\1\PycharmProjects\pythonProject3\venv\lib\site-packages\django\core\servers\basehttp.py None
2023-06-22 17:25:47,332 ERROR Internal Server Error: /admin/News/comment/ C:\Users\1\PycharmProjects\pythonProject3\venv\lib\site-packages\django\utils\log.py (<class 'django.db.utils.OperationalError'>, OperationalError('no such column: News_author.rating'), <traceback object at 0x000000000673BA80>)
Traceback (most recent call last):
  File "C:\Users\1\PycharmProjects\pythonProject3\venv\lib\site-packages\django\db\backends\utils.py", line 89, in _execute
    return self.cursor.execute(sql, params)
  File "C:\Users\1\PycharmProjects\pythonProject3\venv\lib\site-packages\django\db\backends\sqlite3\base.py", line 328, in execute
    return super().execute(query, params)
sqlite3.OperationalError: no such column: News_author.rating

The above exception was the direct cause of the following exception:

Traceback (most recent call last):
  File "C:\Users\1\PycharmProjects\pythonProject3\venv\lib\site-packages\django\core\handlers\exception.py", line 55, in inner
    response = get_response(request)
  File "C:\Users\1\PycharmProjects\pythonProject3\venv\lib\site-packages\django\core\handlers\base.py", line 197, in _get_response
    response = wrapped_callback(request, *callback_args, **callback_kwargs)
  File "C:\Users\1\PycharmProjects\pythonProject3\venv\lib\site-packages\django\contrib\admin\options.py", line 688, in wrapper
    return self.admin_site.admin_view(view)(*args, **kwargs)
  File "C:\Users\1\PycharmProjects\pythonProject3\venv\lib\site-packages\django\utils\decorators.py", line 134, in _wrapper_view
    response = view_func(request, *args, **kwargs)
  File "C:\Users\1\PycharmProjects\pythonProject3\venv\lib\site-packages\django\views\decorators\cache.py", line 62, in _wrapper_view_func
    response = view_func(request, *args, **kwargs)
  File "C:\Users\1\PycharmProjects\pythonProject3\venv\lib\site-packages\django\contrib\admin\sites.py", line 242, in inner
    return view(request, *args, **kwargs)
  File "C:\Users\1\PycharmProjects\pythonProject3\venv\lib\site-packages\django\utils\decorators.py", line 46, in _wrapper
    return bound_method(*args, **kwargs)
  File "C:\Users\1\PycharmProjects\pythonProject3\venv\lib\site-packages\django\utils\decorators.py", line 134, in _wrapper_view
    response = view_func(request, *args, **kwargs)
  File "C:\Users\1\PycharmProjects\pythonProject3\venv\lib\site-packages\django\contrib\admin\options.py", line 2065, in changelist_view
    "selection_note": _("0 of %(cnt)s selected") % {"cnt": len(cl.result_list)},
  File "C:\Users\1\PycharmProjects\pythonProject3\venv\lib\site-packages\django\db\models\query.py", line 380, in __len__
    self._fetch_all()
  File "C:\Users\1\PycharmProjects\pythonProject3\venv\lib\site-packages\django\db\models\query.py", line 1881, in _fetch_all
    self._result_cache = list(self._iterable_class(self))
  File "C:\Users\1\PycharmProjects\pythonProject3\venv\lib\site-packages\django\db\models\query.py", line 91, in __iter__
    results = compiler.execute_sql(
  File "C:\Users\1\PycharmProjects\pythonProject3\venv\lib\site-packages\django\db\models\sql\compiler.py", line 1560, in execute_sql
    cursor.execute(sql, params)
  File "C:\Users\1\PycharmProjects\pythonProject3\venv\lib\site-packages\django\db\backends\utils.py", line 102, in execute
    return super().execute(sql, params)
  File "C:\Users\1\PycharmProjects\pythonProject3\venv\lib\site-packages\django\db\backends\utils.py", line 67, in execute
    return self._execute_with_wrappers(
  File "C:\Users\1\PycharmProjects\pythonProject3\venv\lib\site-packages\django\db\backends\utils.py", line 80, in _execute_with_wrappers
    return executor(sql, params, many, context)
  File "C:\Users\1\PycharmProjects\pythonProject3\venv\lib\site-packages\django\db\backends\utils.py", line 89, in _execute
    return self.cursor.execute(sql, params)
  File "C:\Users\1\PycharmProjects\pythonProject3\venv\lib\site-packages\django\db\utils.py", line 91, in __exit__
    raise dj_exc_value.with_traceback(traceback) from exc_value
  File "C:\Users\1\PycharmProjects\pythonProject3\venv\lib\site-packages\django\db\backends\utils.py", line 89, in _execute
    return self.cursor.execute(sql, params)
  File "C:\Users\1\PycharmProjects\pythonProject3\venv\lib\site-packages\django\db\backends\sqlite3\base.py", line 328, in execute
    return super().execute(query, params)
django.db.utils.OperationalError: no such column: News_author.rating
2023-06-22 17:25:47,337 ERROR "GET /admin/News/comment/ HTTP/1.1" 500 178448 C:\Users\1\PycharmProjects\pythonProject3\venv\lib\site-packages\django\core\servers\basehttp.py None
